<?xml version="1.0" encoding="utf-8"?>
<!-- XACRO version of the URDF generated by SolidWorks to URDF Exporter -->
<robot xmlns:xacro="http://ros.org/wiki/xacro" name="arm">

  <!-- Define properties for reuse -->
  <xacro:property name="color" value="0.75294 0.75294 0.75294 1"/>
  <xacro:property name="effort_limit" value="5"/>
  <xacro:property name="velocity_limit" value="1"/>
  <xacro:property name="joint_limit_lower" value="-1.5"/>
  <xacro:property name="joint_limit_upper" value="1.5"/>

  <!-- Base Link -->
  <link name="base_link">
    <inertial>
      <origin xyz="0.0048255 -1.4572E-16 -0.049574" rpy="0 0 0"/>
      <mass value="511.73"/>
      <inertia ixx="123.26" ixy="1.177E-14" ixz="-6.9518E-16"
               iyy="382.93" iyz="-8.3518E-16" izz="505.33"/>
    </inertial>
    <visual>
      <origin xyz="0 0 0" rpy="0 0 0"/>
      <geometry>
        <mesh filename="package://arm/meshes/base_link.STL"/>
      </geometry>
      <material name="base_color">
        <color rgba="${color}"/>
      </material>
    </visual>
    <collision>
      <origin xyz="0 0 0" rpy="0 0 0"/>
      <geometry>
        <mesh filename="package://arm/meshes/base_link.STL"/>
      </geometry>
    </collision>
  </link>

  <!-- Link1 -->
  <link name="link1">
    <inertial>
      <origin xyz="0.46735 -0.11695 0.053163" rpy="0 0 0"/>
      <mass value="6.3909"/>
      <inertia ixx="0.018479" ixy="0.036498" ixz="1.5041E-05"
               iyy="0.15519" iyz="-3.764E-06" izz="0.16167"/>
    </inertial>
    <visual>
      <origin xyz="0 0 0" rpy="0 0 0"/>
      <geometry>
        <mesh filename="package://arm/meshes/link1.STL"/>
      </geometry>
      <material name="link1_color">
        <color rgba="${color}"/>
      </material>
    </visual>
    <collision>
      <origin xyz="0 0 0" rpy="0 0 0"/>
      <geometry>
        <mesh filename="package://arm/meshes/link1.STL"/>
      </geometry>
    </collision>
  </link>

  <!-- Joint1 -->
  <joint name="joint1" type="revolute">
    <origin xyz="1.43 0 0.236" rpy="0 0 0"/>
    <parent link="base_link"/>
    <child link="link1"/>
    <axis xyz="0 0 1"/>
    <limit lower="${joint_limit_lower}" upper="${joint_limit_upper}"
           effort="${effort_limit}" velocity="${velocity_limit}"/>
  </joint>

  <!-- Link2 -->
  <link name="link2">
    <inertial>
      <origin xyz="-2.0486 -0.1649 0.16936" rpy="0 0 0"/>
      <mass value="522.78"/>
      <inertia ixx="124.33" ixy="-2.7911" ixz="5.6764"
               iyy="438.92" iyz="0.31315" izz="560.68"/>
    </inertial>
    <visual>
      <origin xyz="0 0 0" rpy="0 0 0"/>
      <geometry>
        <mesh filename="package://arm/meshes/link2.STL"/>
      </geometry>
      <material name="link2_color">
        <color rgba="${color}"/>
      </material>
    </visual>
    <collision>
      <origin xyz="0 0 0" rpy="0 0 0"/>
      <geometry>
        <mesh filename="package://arm/meshes/link2.STL"/>
      </geometry>
    </collision>
  </link>

  <!-- Joint2 -->
  <joint name="joint2" type="revolute">
    <origin xyz="0.66887 -0.16738 -0.111" rpy="3.1416 0 0"/>
    <parent link="link1"/>
    <child link="link2"/>
    <axis xyz="0 0 1"/>
    <limit lower="${joint_limit_lower}" upper="${joint_limit_upper}"
           effort="${effort_limit}" velocity="${velocity_limit}"/>
  </joint>

</robot>

